Traceback (most recent call last):
  File "C:\Users\0010594\AppData\Local\Packages\PythonSoftwareFoundation.Python.3.11_qbz5n2kfra8p0\LocalCache\local-packages\Python311\site-packages\jupyter_cache\executors\utils.py", line 58, in single_nb_execution
    executenb(
  File "C:\Users\0010594\AppData\Local\Packages\PythonSoftwareFoundation.Python.3.11_qbz5n2kfra8p0\LocalCache\local-packages\Python311\site-packages\nbclient\client.py", line 1314, in execute
    return NotebookClient(nb=nb, resources=resources, km=km, **kwargs).execute()
           ^^^^^^^^^^^^^^^^^^^^^^^^^^^^^^^^^^^^^^^^^^^^^^^^^^^^^^^^^^^^^^^^^^^^^
  File "C:\Users\0010594\AppData\Local\Packages\PythonSoftwareFoundation.Python.3.11_qbz5n2kfra8p0\LocalCache\local-packages\Python311\site-packages\jupyter_core\utils\__init__.py", line 165, in wrapped
    return loop.run_until_complete(inner)
           ^^^^^^^^^^^^^^^^^^^^^^^^^^^^^^
  File "C:\Program Files\WindowsApps\PythonSoftwareFoundation.Python.3.11_3.11.2544.0_x64__qbz5n2kfra8p0\Lib\asyncio\base_events.py", line 654, in run_until_complete
    return future.result()
           ^^^^^^^^^^^^^^^
  File "C:\Users\0010594\AppData\Local\Packages\PythonSoftwareFoundation.Python.3.11_qbz5n2kfra8p0\LocalCache\local-packages\Python311\site-packages\nbclient\client.py", line 709, in async_execute
    await self.async_execute_cell(
  File "C:\Users\0010594\AppData\Local\Packages\PythonSoftwareFoundation.Python.3.11_qbz5n2kfra8p0\LocalCache\local-packages\Python311\site-packages\nbclient\client.py", line 1062, in async_execute_cell
    await self._check_raise_for_error(cell, cell_index, exec_reply)
  File "C:\Users\0010594\AppData\Local\Packages\PythonSoftwareFoundation.Python.3.11_qbz5n2kfra8p0\LocalCache\local-packages\Python311\site-packages\nbclient\client.py", line 918, in _check_raise_for_error
    raise CellExecutionError.from_cell_and_msg(cell, exec_reply_content)
nbclient.exceptions.CellExecutionError: An error occurred while executing the following cell:
------------------
import pandas as pd
import random
from IPython.display import display, Markdown

csv_path = "data/translations.csv"  # CSV with all translations
data = pd.read_csv(csv_path, delimiter=';')

random_row = data.sample(n=1).iloc[0]  # Select a random row

# Show in a table
table = "| Header | Content |\n"
table += "|--------|---------|\n"
for column, value in random_row.items():
    # Only show the first 400 characters
    truncated_value = str(value)[:400] + "..." if len(str(value)) > 400 else str(value)
    table += f"| {column} | {truncated_value} |\n"
display(Markdown(table))
------------------


[1;31m---------------------------------------------------------------------------[0m
[1;31mModuleNotFoundError[0m                       Traceback (most recent call last)
Cell [1;32mIn[1], line 1[0m
[1;32m----> 1[0m [38;5;28;01mimport[39;00m [38;5;21;01mpandas[39;00m [38;5;28;01mas[39;00m [38;5;21;01mpd[39;00m
[0;32m      2[0m [38;5;28;01mimport[39;00m [38;5;21;01mrandom[39;00m
[0;32m      3[0m [38;5;28;01mfrom[39;00m [38;5;21;01mIPython[39;00m[38;5;21;01m.[39;00m[38;5;21;01mdisplay[39;00m [38;5;28;01mimport[39;00m display, Markdown

[1;31mModuleNotFoundError[0m: No module named 'pandas'

